[11/Apr/2014:10:54:24] ENGINE Bus STARTING
[11/Apr/2014:10:54:24] ENGINE Started monitor thread '_TimeoutMonitor'.
[11/Apr/2014:10:54:24] ENGINE Started monitor thread 'Autoreloader'.
[11/Apr/2014:10:54:24] ENGINE Serving on 0.0.0.0:8084
[11/Apr/2014:10:54:24] ENGINE Bus STARTED
[11/Apr/2014:17:20:47] ENGINE SSLHandshakeError(SSLError(1, '_ssl.c:507: error:14090086:SSL routines:SSL3_GET_SERVER_CERTIFICATE:certificate verify failed'),)
Traceback (most recent call last):
  File "/usr/local/lib/python2.7/site-packages/cherrypy/wsgiserver/wsgiserver2.py", line 1302, in communicate
    req.respond()
  File "/usr/local/lib/python2.7/site-packages/cherrypy/wsgiserver/wsgiserver2.py", line 831, in respond
    self.server.gateway(self).respond()
  File "/usr/local/lib/python2.7/site-packages/cherrypy/wsgiserver/wsgiserver2.py", line 2135, in respond
    response = self.req.server.wsgi_app(self.env, self.start_response)
  File "/usr/local/lib/python2.7/site-packages/cherrypy/_cptree.py", line 290, in __call__
    return app(environ, start_response)
  File "/usr/local/lib/python2.7/site-packages/paste/translogger.py", line 68, in __call__
    return self.application(environ, replacement_start_response)
  File "/usr/local/lib/python2.7/site-packages/flask/app.py", line 1701, in __call__
    return self.wsgi_app(environ, start_response)
  File "/usr/local/lib/python2.7/site-packages/flask/app.py", line 1689, in wsgi_app
    response = self.make_response(self.handle_exception(e))
  File "/usr/local/lib/python2.7/site-packages/flask/app.py", line 1687, in wsgi_app
    response = self.full_dispatch_request()
  File "/usr/local/lib/python2.7/site-packages/flask/app.py", line 1360, in full_dispatch_request
    rv = self.handle_user_exception(e)
  File "/usr/local/lib/python2.7/site-packages/flask/app.py", line 1358, in full_dispatch_request
    rv = self.dispatch_request()
  File "/usr/local/lib/python2.7/site-packages/flask/app.py", line 1344, in dispatch_request
    return self.view_functions[rule.endpoint](**req.view_args)
  File "/usr/local/lib/python2.7/site-packages/flask_oauth.py", line 429, in decorated
    data = self.handle_oauth2_response()
  File "/usr/local/lib/python2.7/site-packages/flask_oauth.py", line 400, in handle_oauth2_response
    resp, content = self._client.request(url, self.access_token_method)
  File "/usr/local/lib/python2.7/site-packages/oauth2/__init__.py", line 682, in request
    connection_type=connection_type)
  File "/usr/local/lib/python2.7/site-packages/httplib2/__init__.py", line 1570, in request
    (response, content) = self._request(conn, authority, uri, request_uri, method, body, headers, redirections, cachekey)
  File "/usr/local/lib/python2.7/site-packages/httplib2/__init__.py", line 1317, in _request
    (response, content) = self._conn_request(conn, request_uri, method, body, headers)
  File "/usr/local/lib/python2.7/site-packages/httplib2/__init__.py", line 1290, in _conn_request
    conn.connect()
  File "/usr/local/lib/python2.7/site-packages/httplib2/__init__.py", line 1044, in connect
    raise SSLHandshakeError(e)
SSLHandshakeError: [Errno 1] _ssl.c:507: error:14090086:SSL routines:SSL3_GET_SERVER_CERTIFICATE:certificate verify failed

[11/Apr/2014:17:23:31] ENGINE SSLHandshakeError(SSLError(1, '_ssl.c:507: error:14090086:SSL routines:SSL3_GET_SERVER_CERTIFICATE:certificate verify failed'),)
Traceback (most recent call last):
  File "/usr/local/lib/python2.7/site-packages/cherrypy/wsgiserver/wsgiserver2.py", line 1302, in communicate
    req.respond()
  File "/usr/local/lib/python2.7/site-packages/cherrypy/wsgiserver/wsgiserver2.py", line 831, in respond
    self.server.gateway(self).respond()
  File "/usr/local/lib/python2.7/site-packages/cherrypy/wsgiserver/wsgiserver2.py", line 2135, in respond
    response = self.req.server.wsgi_app(self.env, self.start_response)
  File "/usr/local/lib/python2.7/site-packages/cherrypy/_cptree.py", line 290, in __call__
    return app(environ, start_response)
  File "/usr/local/lib/python2.7/site-packages/paste/translogger.py", line 68, in __call__
    return self.application(environ, replacement_start_response)
  File "/usr/local/lib/python2.7/site-packages/flask/app.py", line 1701, in __call__
    return self.wsgi_app(environ, start_response)
  File "/usr/local/lib/python2.7/site-packages/flask/app.py", line 1689, in wsgi_app
    response = self.make_response(self.handle_exception(e))
  File "/usr/local/lib/python2.7/site-packages/flask/app.py", line 1687, in wsgi_app
    response = self.full_dispatch_request()
  File "/usr/local/lib/python2.7/site-packages/flask/app.py", line 1360, in full_dispatch_request
    rv = self.handle_user_exception(e)
  File "/usr/local/lib/python2.7/site-packages/flask/app.py", line 1358, in full_dispatch_request
    rv = self.dispatch_request()
  File "/usr/local/lib/python2.7/site-packages/flask/app.py", line 1344, in dispatch_request
    return self.view_functions[rule.endpoint](**req.view_args)
  File "/usr/local/lib/python2.7/site-packages/flask_oauth.py", line 429, in decorated
    data = self.handle_oauth2_response()
  File "/usr/local/lib/python2.7/site-packages/flask_oauth.py", line 400, in handle_oauth2_response
    resp, content = self._client.request(url, self.access_token_method)
  File "/usr/local/lib/python2.7/site-packages/oauth2/__init__.py", line 682, in request
    connection_type=connection_type)
  File "/usr/local/lib/python2.7/site-packages/httplib2/__init__.py", line 1570, in request
    (response, content) = self._request(conn, authority, uri, request_uri, method, body, headers, redirections, cachekey)
  File "/usr/local/lib/python2.7/site-packages/httplib2/__init__.py", line 1317, in _request
    (response, content) = self._conn_request(conn, request_uri, method, body, headers)
  File "/usr/local/lib/python2.7/site-packages/httplib2/__init__.py", line 1252, in _conn_request
    conn.connect()
  File "/usr/local/lib/python2.7/site-packages/httplib2/__init__.py", line 1044, in connect
    raise SSLHandshakeError(e)
SSLHandshakeError: [Errno 1] _ssl.c:507: error:14090086:SSL routines:SSL3_GET_SERVER_CERTIFICATE:certificate verify failed

